2020-10-16 00:33:24,025 INFO    MainThread:19020 [internal.py:wandb_internal():62] W&B internal server running at pid: 19020
2020-10-16 00:33:24,027 DEBUG   HandlerThread:19020 [handler.py:handle_request():54] handle_request: check_version
2020-10-16 00:33:24,027 INFO    WriterThread:19020 [datastore.py:open_for_write():76] open: wandb\run-20201016_003323-1q9qtvqp\run-1q9qtvqp.wandb
2020-10-16 00:33:24,028 DEBUG   SenderThread:19020 [sender.py:send():88] send: header
2020-10-16 00:33:24,028 DEBUG   SenderThread:19020 [sender.py:send():88] send: request
2020-10-16 00:33:24,028 DEBUG   SenderThread:19020 [sender.py:send_request():97] send_request: check_version
2020-10-16 00:33:24,030 DEBUG   Thread-8  :19020 [connectionpool.py:_new_conn():943] Starting new HTTPS connection (1): pypi.org:443
2020-10-16 00:33:24,035 DEBUG   SenderThread:19020 [sender.py:send():88] send: run
2020-10-16 00:33:24,214 DEBUG   SenderThread:19020 [util.py:is_cygwin_git():315] Failed checking if running in CYGWIN due to: FileNotFoundError(2, 'The system cannot find the file specified', None, 2, None)
2020-10-16 00:33:24,216 DEBUG   SenderThread:19020 [cmd.py:execute():719] Popen(['git', 'cat-file', '--batch-check'], cwd=D:\IIT\Coursework\CS6886, universal_newlines=False, shell=None, istream=<valid stream>)
2020-10-16 00:33:24,258 DEBUG   SenderThread:19020 [connectionpool.py:_new_conn():943] Starting new HTTPS connection (1): api.wandb.ai:443
2020-10-16 00:33:25,410 DEBUG   SenderThread:19020 [connectionpool.py:_new_conn():943] Starting new HTTPS connection (1): api.wandb.ai:443
2020-10-16 00:33:27,430 DEBUG   SenderThread:19020 [connectionpool.py:_new_conn():943] Starting new HTTPS connection (1): api.wandb.ai:443
2020-10-16 00:33:27,430 ERROR   SenderThread:19020 [retry.py:__call__():111] Retry attempt failed:
Traceback (most recent call last):
  File "C:\Users\Dhruv Laad\AppData\Roaming\Python\Python37\site-packages\urllib3\connection.py", line 160, in _new_conn
    (self._dns_host, self.port), self.timeout, **extra_kw
  File "C:\Users\Dhruv Laad\AppData\Roaming\Python\Python37\site-packages\urllib3\util\connection.py", line 61, in create_connection
    for res in socket.getaddrinfo(host, port, family, socket.SOCK_STREAM):
  File "D:\Applications\Anaconda\envs\minerl\lib\socket.py", line 752, in getaddrinfo
    for res in _socket.getaddrinfo(host, port, family, type, proto, flags):
socket.gaierror: [Errno 11001] getaddrinfo failed

During handling of the above exception, another exception occurred:

Traceback (most recent call last):
  File "C:\Users\Dhruv Laad\AppData\Roaming\Python\Python37\site-packages\urllib3\connectionpool.py", line 677, in urlopen
    chunked=chunked,
  File "C:\Users\Dhruv Laad\AppData\Roaming\Python\Python37\site-packages\urllib3\connectionpool.py", line 381, in _make_request
    self._validate_conn(conn)
  File "C:\Users\Dhruv Laad\AppData\Roaming\Python\Python37\site-packages\urllib3\connectionpool.py", line 978, in _validate_conn
    conn.connect()
  File "C:\Users\Dhruv Laad\AppData\Roaming\Python\Python37\site-packages\urllib3\connection.py", line 309, in connect
    conn = self._new_conn()
  File "C:\Users\Dhruv Laad\AppData\Roaming\Python\Python37\site-packages\urllib3\connection.py", line 172, in _new_conn
    self, "Failed to establish a new connection: %s" % e
urllib3.exceptions.NewConnectionError: <urllib3.connection.HTTPSConnection object at 0x00000218D2A65108>: Failed to establish a new connection: [Errno 11001] getaddrinfo failed

During handling of the above exception, another exception occurred:

Traceback (most recent call last):
  File "C:\Users\Dhruv Laad\AppData\Roaming\Python\Python37\site-packages\requests\adapters.py", line 449, in send
    timeout=timeout
  File "C:\Users\Dhruv Laad\AppData\Roaming\Python\Python37\site-packages\urllib3\connectionpool.py", line 727, in urlopen
    method, url, error=e, _pool=self, _stacktrace=sys.exc_info()[2]
  File "C:\Users\Dhruv Laad\AppData\Roaming\Python\Python37\site-packages\urllib3\util\retry.py", line 439, in increment
    raise MaxRetryError(_pool, url, error or ResponseError(cause))
urllib3.exceptions.MaxRetryError: HTTPSConnectionPool(host='api.wandb.ai', port=443): Max retries exceeded with url: /graphql (Caused by NewConnectionError('<urllib3.connection.HTTPSConnection object at 0x00000218D2A65108>: Failed to establish a new connection: [Errno 11001] getaddrinfo failed'))

During handling of the above exception, another exception occurred:

Traceback (most recent call last):
  File "D:\Applications\Anaconda\envs\minerl\lib\site-packages\wandb\old\retry.py", line 96, in __call__
    result = self._call_fn(*args, **kwargs)
  File "D:\Applications\Anaconda\envs\minerl\lib\site-packages\wandb\internal\internal_api.py", line 128, in execute
    return self.client.execute(*args, **kwargs)
  File "D:\Applications\Anaconda\envs\minerl\lib\site-packages\wandb\vendor\gql-0.2.0\gql\client.py", line 52, in execute
    result = self._get_result(document, *args, **kwargs)
  File "D:\Applications\Anaconda\envs\minerl\lib\site-packages\wandb\vendor\gql-0.2.0\gql\client.py", line 60, in _get_result
    return self.transport.execute(document, *args, **kwargs)
  File "D:\Applications\Anaconda\envs\minerl\lib\site-packages\wandb\vendor\gql-0.2.0\gql\transport\requests.py", line 38, in execute
    request = requests.post(self.url, **post_args)
  File "C:\Users\Dhruv Laad\AppData\Roaming\Python\Python37\site-packages\requests\api.py", line 119, in post
    return request('post', url, data=data, json=json, **kwargs)
  File "C:\Users\Dhruv Laad\AppData\Roaming\Python\Python37\site-packages\requests\api.py", line 61, in request
    return session.request(method=method, url=url, **kwargs)
  File "C:\Users\Dhruv Laad\AppData\Roaming\Python\Python37\site-packages\requests\sessions.py", line 530, in request
    resp = self.send(prep, **send_kwargs)
  File "C:\Users\Dhruv Laad\AppData\Roaming\Python\Python37\site-packages\requests\sessions.py", line 643, in send
    r = adapter.send(request, **kwargs)
  File "C:\Users\Dhruv Laad\AppData\Roaming\Python\Python37\site-packages\requests\adapters.py", line 516, in send
    raise ConnectionError(e, request=request)
requests.exceptions.ConnectionError: HTTPSConnectionPool(host='api.wandb.ai', port=443): Max retries exceeded with url: /graphql (Caused by NewConnectionError('<urllib3.connection.HTTPSConnection object at 0x00000218D2A65108>: Failed to establish a new connection: [Errno 11001] getaddrinfo failed'))
2020-10-16 00:33:32,338 DEBUG   SenderThread:19020 [connectionpool.py:_new_conn():943] Starting new HTTPS connection (1): api.wandb.ai:443
2020-10-16 00:33:40,547 DEBUG   SenderThread:19020 [connectionpool.py:_new_conn():943] Starting new HTTPS connection (1): api.wandb.ai:443
2020-10-16 00:33:54,036 DEBUG   HandlerThread:19020 [handler.py:handle_request():54] handle_request: shutdown
2020-10-16 00:33:54,036 INFO    HandlerThread:19020 [handler.py:finish():267] shutting down handler
2020-10-16 00:33:54,053 INFO    WriterThread:19020 [datastore.py:close():257] close: wandb\run-20201016_003323-1q9qtvqp\run-1q9qtvqp.wandb
2020-10-16 00:33:56,748 DEBUG   SenderThread:19020 [connectionpool.py:_new_conn():943] Starting new HTTPS connection (1): api.wandb.ai:443
2020-10-16 00:34:36,040 DEBUG   SenderThread:19020 [connectionpool.py:_new_conn():943] Starting new HTTPS connection (1): api.wandb.ai:443
